Workbook

Sheet Code_book_v3.3
A1: Guidance Document Number | B1: lungns_001 | D1: Year of publication (YYYY) | E1: NA | J1: Link to included public health guidance:
J2: https://docs.google.com/spreadsheets/d/1U6FT22zcSiTIgCpsi59hsJdafV3-jaXUUoqXH4dbE2I/edit?usp=sharing
C3: 1 | F3: 1.X | I3: 1.X.X | L3: 1.X.X.X | O3: 1.X.X.X.X | R3: 1.X.X.X.X.X
A4: Health protective action: wildfire smoke | B4: Indicates whether the document describes one or more individual-level, self-protective health behaviour in the context of wildfire smoke (WFS) | C4: 1 | D4: Yes/No: Describes protective actions | E4: YES | F4: 1.1 | G4: Yes/No: Filter air (specify) | H4: YES | I4: 1.1.1 | J4: Yes/No: Use air cleaner/purifier | K4: YES | L4: 1.1.1.1 | M4: Yes/No: Use HEPA filter | N4: YES
I5: 1.1.2 | J5: Yes/No: Run HVAC/central heating continuously | K5: YES | L5: 1.1.2.1 | M5: Yes/No: Records filter type | N5: NO | O5: 1.1.2.1.1 | P5: STR: Records filter type
I6: 1.1.3 | J6: Yes/No: Filtering air in vehicle (eg, recirculation mode) | K6: YES
F7: 1.2 | G7: Yes/No: Reduce outdoor exercise | H7: YES
F8: 1.3 | G8: Yes/No: Stay indoors | H8: YES | I8: 1.3.1 | J8: Yes/No: Specifies with doors and windows closed | K8: YES
F9: 1.4 | G9: Yes/No: Wear a mask | H9: YES | I9: 1.4.1 | J9: Yes/No: N95 | K9: YES
I10: 1.4.2 | J10: Yes/No: KN95 | K10: NO
I11: 1.4.3 | J11: Yes/No: Respirator | K11: NO
I12: 1.4.4 | J12: Yes/No: Surgical mask | K12: NO
I13: 1.4.5 | J13: Yes/No: AGAINST certain type of mask | K13: NO | L13: 1.4.5.1 | M13: STR: Against certain type of mask
I14: 1.4.6 | J14: Yes/No: FOR OTHER certain type of mask | K14: NO | L14: 1.4.6.1 | M14: STR: FOR OTHER certain type of mask
F15: 1.5 | G15: Yes/No: Check air quality | H15: YES | I15: 1.5.1 | J15: Yes/No: Check outdoor air quality | K15: YES | L15: 1.5.1.1 | M15: Yes/No: Specifies how to check outdoor air quality | N15: YES | O15: 1.5.1.1.1 | P15: Yes/No: Specifies government source for air quality | Q15: YES | R15: 1.5.1.1.1.1 | S15: Yes/No: ECCC/Weather Canada | T15: YES
R16: 1.5.1.1.1.2 | S16: Yes/No: BC Government | T16: NO
R17: 1.5.1.1.1.3 | S17: Yes/No: FireSmoke | T17: NO
O18: 1.5.1.1.2 | P18: Yes/No: Specifies crowdsource/commercial source for air quality | Q18: NO | R18: 1.5.1.1.2.1 | S18: Yes/No: Purple air | T18: NO
R19: 1.5.1.1.2.2 | S19: Yes/No: IQair | T19: NO
L20: 1.5.1.2 | M20: Yes/No: Specifies actions to take based on outdoor air quality | O20: 1.5.1.2.1 | P20: STR: Recommended action based on outdoor air quality
I21: 1.5.2 | J21: Yes/No: Check indoor air quality | K21: NO | L21: 1.5.2.1 | M21: Yes/No: Specifies monitor type | N21: NO | O21: 1.5.2.1.1 | P21: STR: Monitor type
L22: 1.5.2.2 | M22: Yes/No: Specifies action to take based on air monitor results | N22: NO | O22: 1.5.2.2.1 | P22: STR: Recommended action based on air quality
F23: 1.6 | G23: Yes/No: Other specified | H23: YES | I23: 1.6.1 | J23: STR: Other health protective behaviour specified
C25: 2 | F25: 2.X | I25: 2.X.X
A26: Target audience | B26: Indicates whether the document includes an explicit statement of the population group(s) to whom the document is directed | C26: 2 | D26: Yes/No: is an explicit statement of target audience present? | E26: NO | F26: 2.1 | G26: Yes/No: General population | H26: NO
F27: 2.2 | G27: Yes/No: Children/infants | H27: NO
F28: 2.3 | G28: Yes/No: Older populations/elderly | H28: NO
F29: 2.4 | G29: Yes/No: Pregnant populations | H29: NO
F30: 2.5 | G30: Yes/No: Current lung disease | H30: NO
F31: 2.6 | G31: Yes/No: Current other health condition (eg, diabetes) | H31: NO | I31: 2.6.1 | J31: STR: Specify other health condition
F32: 2.7 | G32: Other | H32: NO | I32: 2.7.1 | J32: STR: Specify other
C34: 3 | F34: 3.X | I34: 3.X.X
A35: Guidance goals | B35: Indicates whether the document includes an explicit statement of its goal (i.e., goal of recommendation(s) overall) | C35: 3 | D35: Yes/No: is an explicit statement of guidance goal(s) present? | E35: NO | F35: 3.1 | G35: Yes/No: Protect health (general) | H35: NO
F36: 3.2 | G36: Yes/No: Protect lung health | H36: NO
F37: 3.3 | G37: Yes/No: Protect health (other specific, not lung) | H37: NO | I37: 3.3.1 | J37: STR: Specify protect health (other specific, not lung)
F38: 3.4 | G38: Yes/No: Inform decisions | H38: NO
F39: 3.5 | G39: Yes/No: Other | H39: NO | I39: 3.4.1 | J39: STR: Other guidance goal (specify)
C41: 4 | F41: 4.X | I41: 4.X.X
A42: Author and author statement | B42: Indicates whether the document describes the authors of the guidance at the individual level | C42: 4 | D42: Yes/No: Is/are author(s) described at an individual level? (eg, not at the the organizational level only (e.g., BCCDC) or not at all) | E42: NO | F42: 4.1 | G42: Yes/No: individual authors' names | H42: NO
F43: 4.2 | G43: Yes/No: individuals authors' accreditation | H43: NO
...

Sheet Data_extraction_working
A2: doc_id | B2: source_name | C2: include_wfs_health_action | D2: use_air_cleaner | E2: use_HEPA_filter | F2: run_HVAC_continuous | G2: filter_air_vehicle | H2: run_HVAC_filter_specified | I2: run_HVAC_filter_type_txt | J2: reduce_outdoor_exercise | K2: stay_indoors | L2: stay_indoors_doors_windows_closed | M2: wear_mask | N2: wear_mask_N95 | O2: wear_mask_KN95 | P2: wear_mask_respirator | Q2: wear_mask_surgical | R2: wear_mask_against_specified | S2: wear_mask_against_txt | T2: wear_mask_other | U2: wear_mask_other_txt | V2: check_air_quality | W2: check_outdoor_AQ | X2: check_outdoor_AQ_method | Y2: check_outdoor_AQ_govt | Z2: check_outdoor_AQ_govt_ECCC | AA2: check_outdoor_AQ_govt_BC | AB2: check_outdoor_AQ_govt_FireSmoke | AC2: check_outdoor_AQ_crowdsource | AD2: check_outdoor_AQ_PurpleAir | AE2: check_outdoor_AQ_IQair | AF2: outdoor_AQ_action_specified | AG2: outdoor_AQ_action_txt | AH2: monitor_indoor_AQ | AI2: indoor_monitor_type_specified | AJ2: indoor_monitor_type_txt | AK2: indoor_monitor_action_specified | AL2: indoor_monitor_action_txt | AM2: other_health_action | AN2: other_health_action_txt | AO2: target_audience_present | AP2: target_audience_general_pop | AQ2: target_group_children_infants | AR2: target_group_older | AS2: target_group_pregnant | AT2: target_group_pregnant | AU2: target_group_current_lung_disease | AV2: target_group_current_other_health | AW2: target_group_current_other_health_txt | AX2: target_group_current_other | AY2: target_group_current_other_txt | AZ2: guidance_goal_present | BA2: guidance_goal_protect_health_general | BB2: guidance_goal_protect_lung_health | BC2: guidance_goal_protect_health_other | BD2: guidance_goal_protect_health_other_txt | BE2: guidance_goal_informs_decisions | BF2: guidance_goal_other | BG2: guidance_goal_other_txt | BH2: author_individual_level | BI2: author_names_present | BJ2: author_accreditation_present | BK2: author_additional_info_present | BL2: author_additional_info_txt | BM2: dev_process_described | BN2: dev_process_details_txt | BO2: multi_language_available | BP2: language_french | BQ2: language_chinese | BR2: language_hindi | BS2: language_punjabi | BT2: language_spanish | BU2: language_other_specified | BV2: language_other_txt | BW2: benefits_present | BX2: benefits_hepa | BY2: benefits_HEPA_improves_air_quality | BZ2: benefits_HEPA_improves_lung_health | CA2: benefits_HEPA_improves_other_health | CB2: benefits_HEPA_improves_other_non_health | CC2: benefits_DIY | CD2: benefits_DIY_improves_air_quality | CE2: benefits_DIY_improves_lung_health | CF2: benefits_DIY_improves_other_health | CG2: benefits_DIY_improves_other_non_health | CH2: benefits_indoor | CI2: benefits_indoor_improves_air_quality | CJ2: benefits_indoor_improves_lung_health | CK2: benefits_indoor_improves_other_health | CL2: benefits_indoor_improves_other_non_health | CM2: benefits_reduce_outdoor | CN2: benefits_present | CO2: benefits_hepa | CP2: benefits_HEPA_improves_air_quality | CQ2: benefits_HEPA_improves_lung_health | CR2: benefits_HEPA_improves_other_health | CS2: benefits_HEPA_improves_other_non_health | CT2: benefits_DIY | CU2: benefits_DIY_improves_air_quality | CV2: benefits_DIY_improves_lung_health | CW2: benefits_DIY_improves_other_health | CX2: benefits_DIY_improves_other_non_health | CY2: bruden_present | CZ2: burden_hepa | DA2: burden_HEPA_upfront_cost | DB2: burden_HEPA_main_cost | DC2: burden_HEPA_noise | DD2: burden_HEPA_other | DE2: burden_diy | DF2: burden_diy_main_cost | DG2: burden_diy_noise | DH2: burden_diy_other | DI2: burden_indoor | DJ2: burden_indoor_work | DK2: burden_indoor_well_being | DL2: burden_indoor_other | DM2: burden_outdoor | DN2: burden_outdoor_work | DO2: burden_outdoor_well_being | DP2: burden_outdoor_other | DQ2: burden_mask | DR2: burden_mask_work | DS2: burden_mask_well_being | DT2: burden_mask_cost | DU2: burden_mask_other | DV2: burden_other | DW2: burden_other_txt | DX2: effectsize_present | DY2: effectsize_HEPA_present | DZ2: effectsize_HEPA_air_quality | EA2: effectsize_HEPA_lung_health | EB2: effectsize_HEPA_other_health | EC2: effectsize_HEPA_other | ED2: effectsize_HEPA_txt | EE2: effectsize_DIY_present | EF2: effectsize_DIY_air_quality | EG2: effectsize_DIY_lung_health | EH2: effectsize_DIY_other_health | EI2: effectsize_DIY_other | EJ2: effectsize_DIY_txt | EK2: effectsize_stay_indoors_present | EL2: effectsize_stay_indoors_reduce_exposure | EM2: effectsize_stay_indoors_lung_health | EN2: effectsize_stay_indoors_other_health | EO2: effectsize_stay_indoors_other | EP2: effectsize_stay_indoors_txt | EQ2: effectsize_reduce_exercise_present | ER2: effectsize_reduce_exercise_reduce_exposure | ES2: effectsize_reduce_exercise_lung_health | ET2: effectsize_reduce_exercise_other_health | EU2: effectsize_reduce_exercise_other | EV2: effectsize_reduce_exercise_txt | EW2: effectsize_mask_present | EX2: effectsize_mask_reduce_exposure | EY2: effectsize_mask_lung_health | EZ2: effectsize_mask_other_health | FA2: effectsize_mask_other | FB2: effectsize_mask_txt | FC2: effectsize_other_action_present | FD2: effectsize_other_action_txt | FE2: effectsize_burden_present | FF2: effectsize_burden_HEPA_present | FG2: effectsize_burden_HEPA_air_quality | FH2: effectsize_burden_HEPA_lung_health | FI2: effectsize_burden_HEPA_other_health | FJ2: effectsize_burden_HEPA_other | FK2: effectsize_burden_HEPA_txt | FL2: effectsize_burden_DIY_present | FM2: effectsize_burden_DIY_air_quality | FN2: effectsize_burden_DIY_lung_health | FO2: effectsize_burden_DIY_other_health | FP2: effectsize_burden_DIY_other | FQ2: effectsize_burden_DIY_txt | FR2: effectsize_burden_stay_indoors_present | FS2: effectsize_burden_stay_indoors_reduce_exposure | FT2: effectsize_burden_stay_indoors_lung_health | FU2: effectsize_burden_stay_indoors_other_health | FV2: effectsize_burden_stay_indoors_other | FW2: effectsize_burden_stay_indoors_txt | FX2: effectsize_burden_reduce_exercise_present | FY2: effectsize_burden_reduce_exercise_reduce_exposure | FZ2: effectsize_burden_reduce_exercise_lung_health | GA2: effectsize_burden_reduce_exercise_other_health | GB2: effectsize_burden_reduce_exercise_other | GC2: effectsize_burden_reduce_exercise_txt | GD2: effectsize_burden_mask_present | GE2: effectsize_burden_mask_reduce_exposure | GF2: effectsize_burden_mask_lung_health | GG2: effectsize_burden_mask_other_health | GH2: effectsize_burden_mask_other | GI2: effectsize_burden_mask_txt | GJ2: effectsize_burden_other_action_present | GK2: effectsize_burden_other_action_txt | GL2: evidence_quality_present | GM2: evidence_quality_HEPA | GN2: evidence_quality_DIY | GO2: evidence_quality_stay_indoors | GP2: evidence_quality_reduce_exercise | GQ2: evidence_quality_mask | GR2: evidence_quality_other | GS2: evidence_quality_other_action_txt | GT2: references_scientific_publications | GU2: references_scientific_publications_txt
A3: ='Code_book_v3.3'!B1 -> lungns_001 | B3: ='Code_book_v3.3'!E1 -> NA | C3: ='Code_book_v3.3'!E4 -> YES | D3: ='Code_book_v3.3'!K4 -> YES | E3: ='Code_book_v3.3'!N4 -> YES | F3: ='Code_book_v3.3'!K5 -> YES | G3: ='Code_book_v3.3'!K6 -> YES | H3: ='Code_book_v3.3'!N5 -> NO | I3: ='Code_book_v3.3'!Q5 -> 0 | J3: ='Code_book_v3.3'!H7 -> YES | K3: ='Code_book_v3.3'!H8 -> YES | L3: ='Code_book_v3.3'!K8 -> YES | M3: ='Code_book_v3.3'!H9 -> YES | N3: ='Code_book_v3.3'!K9 -> YES | O3: ='Code_book_v3.3'!K10 -> NO | P3: ='Code_book_v3.3'!K11 -> NO | Q3: ='Code_book_v3.3'!K12 -> NO | R3: ='Code_book_v3.3'!K13 -> NO | S3: ='Code_book_v3.3'!N13 -> 0 | T3: ='Code_book_v3.3'!K14 -> NO | U3: ='Code_book_v3.3'!N14 -> 0 | V3: ='Code_book_v3.3'!H15 -> YES | W3: ='Code_book_v3.3'!K15 -> YES | X3: ='Code_book_v3.3'!N15 -> YES | Y3: ='Code_book_v3.3'!Q15 -> YES | Z3: ='Code_book_v3.3'!T15 -> YES | AA3: ='Code_book_v3.3'!T16 -> NO | AB3: ='Code_book_v3.3'!T17 -> NO | AC3: ='Code_book_v3.3'!Q18 -> NO | AD3: ='Code_book_v3.3'!T18 -> NO | AE3: ='Code_book_v3.3'!T19 -> NO | AF3: ='Code_book_v3.3'!N20 -> 0 | AG3: ='Code_book_v3.3'!Q20 -> 0 | AH3: ='Code_book_v3.3'!K21 -> NO | AI3: ='Code_book_v3.3'!N21 -> NO | AJ3: ='Code_book_v3.3'!Q21 -> 0 | AK3: ='Code_book_v3.3'!N22 -> NO | AL3: ='Code_book_v3.3'!Q22 -> 0 | AM3: ='Code_book_v3.3'!H23 -> YES | AN3: ='Code_book_v3.3'!K23 -> 0 | AO3: ='Code_book_v3.3'!E26 -> NO | AP3: ='Code_book_v3.3'!H26 -> NO | AQ3: ='Code_book_v3.3'!H27 -> NO | AR3: ='Code_book_v3.3'!H28 -> NO | AS3: ='Code_book_v3.3'!H29 -> NO | AT3: ='Code_book_v3.3'!H29 -> NO | AU3: ='Code_book_v3.3'!H30 -> NO | AV3: ='Code_book_v3.3'!H31 -> NO | AW3: ='Code_book_v3.3'!K31 -> 0 | AX3: ='Code_book_v3.3'!H32 -> NO | AY3: ='Code_book_v3.3'!K32 -> 0 | AZ3: ='Code_book_v3.3'!E35 -> NO | BA3: ='Code_book_v3.3'!H35 -> NO | BB3: ='Code_book_v3.3'!H36 -> NO | BC3: ='Code_book_v3.3'!H37 -> NO | BD3: ='Code_book_v3.3'!K37 -> 0 | BE3: ='Code_book_v3.3'!H39 -> NO | BF3: ='Code_book_v3.3'!H39 -> NO | BG3: ='Code_book_v3.3'!K39 -> 0 | BH3: ='Code_book_v3.3'!E42 -> NO | BI3: ='Code_book_v3.3'!H42 -> NO | BJ3: ='Code_book_v3.3'!H43 -> NO | BK3: ='Code_book_v3.3'!H44 -> NO | BL3: ='Code_book_v3.3'!K44 -> 0 | BM3: ='Code_book_v3.3'!E47 -> NO | BN3: ='Code_book_v3.3'!H47 -> 0 | BO3: ='Code_book_v3.3'!E50 -> NO | BP3: ='Code_book_v3.3'!H50 -> NO | BQ3: ='Code_book_v3.3'!H51 -> NO | BR3: ='Code_book_v3.3'!H52 -> NO | BS3: ='Code_book_v3.3'!H53 -> NO | BT3: ='Code_book_v3.3'!H54 -> NO | BU3: ='Code_book_v3.3'!H55 -> NO | BV3: ='Code_book_v3.3'!K55 -> 0 | BW3: ='Code_book_v3.3'!E59 -> NO | BX3: ='Code_book_v3.3'!H59 -> NO | BY3: ='Code_book_v3.3'!K59 -> NO | BZ3: ='Code_book_v3.3'!K60 -> NO | CA3: ='Code_book_v3.3'!K61 -> NO | CB3: ='Code_book_v3.3'!K62 -> NO | CC3: ='Code_book_v3.3'!H63 -> NO | CD3: ='Code_book_v3.3'!K63 -> NO | CE3: ='Code_book_v3.3'!K64 -> NO | CF3: ='Code_book_v3.3'!K65 -> NO | CG3: ='Code_book_v3.3'!K66 -> NO | CH3: ='Code_book_v3.3'!H67 -> NO | CI3: ='Code_book_v3.3'!K67 -> NO | CJ3: ='Code_book_v3.3'!K68 -> NO | CK3: ='Code_book_v3.3'!K69 -> NO | CL3: ='Code_book_v3.3'!K70 -> NO | CM3: ='Code_book_v3.3'!H71 -> NO | CN3: ='Code_book_v3.3'!V59 -> 0 | CO3: ='Code_book_v3.3'!Y59 -> 0 | CP3: ='Code_book_v3.3'!AB59 -> 0 | CQ3: ='Code_book_v3.3'!AB60 -> 0 | CR3: ='Code_book_v3.3'!AB61 -> 0 | CS3: ='Code_book_v3.3'!AB62 -> 0 | CT3: ='Code_book_v3.3'!Y63 -> 0 | CU3: ='Code_book_v3.3'!AB63 -> 0 | CV3: ='Code_book_v3.3'!AB64 -> 0 | CW3: ='Code_book_v3.3'!AB65 -> 0 | CX3: ='Code_book_v3.3'!AB66 -> 0 | CY3: ='Code_book_v3.3'!E82 -> NO | CZ3: ='Code_book_v3.3'!H82 -> NO | DA3: ='Code_book_v3.3'!K82 -> NO | DB3: ='Code_book_v3.3'!K83 -> NO | DC3: ='Code_book_v3.3'!K84 -> NO | DD3: ='Code_book_v3.3'!K85 -> NO | DE3: ='Code_book_v3.3'!H86 -> NO | DF3: ='Code_book_v3.3'!K86 -> NO | DG3: ='Code_book_v3.3'!K88 -> NO | DH3: ='Code_book_v3.3'!K89 -> NO | DI3: ='Code_book_v3.3'!H90 -> NO | DJ3: ='Code_book_v3.3'!K90 -> NO | DK3: ='Code_book_v3.3'!K91 -> NO | DL3: ='Code_book_v3.3'!K92 -> NO | DM3: ='Code_book_v3.3'!H93 -> NO | DN3: ='Code_book_v3.3'!K93 -> NO | DO3: ='Code_book_v3.3'!K94 -> NO | DP3: ='Code_book_v3.3'!K95 -> NO | DQ3: ='Code_book_v3.3'!H96 -> NO | DR3: ='Code_book_v3.3'!K96 -> NO | DS3: ='Code_book_v3.3'!K97 -> NO | DT3: ='Code_book_v3.3'!K98 -> NO | DU3: ='Code_book_v3.3'!K99 -> NO | DV3: ='Code_book_v3.3'!H100 -> NO | DW3: ='Code_book_v3.3'!K100 -> 0 | DX3: ='Code_book_v3.3'!E103 -> NO | DY3: ='Code_book_v3.3'!H103 -> NO | DZ3: ='Code_book_v3.3'!K103 -> NO | EA3: ='Code_book_v3.3'!K104 -> NO | EB3: ='Code_book_v3.3'!K105 -> NO | EC3: ='Code_book_v3.3'!K106 -> NO | ED3: ='Code_book_v3.3'!N103 -> 0 | EE3: ='Code_book_v3.3'!H107 -> NO | EF3: ='Code_book_v3.3'!K107 -> NO | EG3: ='Code_book_v3.3'!K108 -> NO | EH3: ='Code_book_v3.3'!K109 -> NO | EI3: ='Code_book_v3.3'!K110 -> NO | EJ3: ='Code_book_v3.3'!N107 -> 0 | EK3: ='Code_book_v3.3'!H111 -> NO | EL3: ='Code_book_v3.3'!K111 -> NO | EM3: ='Code_book_v3.3'!K111 -> NO | EN3: ='Code_book_v3.3'!K112 -> NO | EO3: ='Code_book_v3.3'!K114 -> NO | EP3: ='Code_book_v3.3'!N111 -> 0 | EQ3: ='Code_book_v3.3'!H115 -> NO | ER3: ='Code_book_v3.3'!K115 -> NO | ES3: ='Code_book_v3.3'!K116 -> NO | ET3: ='Code_book_v3.3'!K117 -> NO | EU3: ='Code_book_v3.3'!K118 -> NO | EV3: ='Code_book_v3.3'!N115 -> 0 | EW3: ='Code_book_v3.3'!H119 -> NO | EX3: ='Code_book_v3.3'!K119 -> NO | EY3: ='Code_book_v3.3'!K120 -> NO | EZ3: ='Code_book_v3.3'!K121 -> NO | FA3: ='Code_book_v3.3'!K122 -> NO | FB3: ='Code_book_v3.3'!N119 -> 0 | FC3: ='Code_book_v3.3'!H123 -> NO | FD3: ='Code_book_v3.3'!K123 -> 0 | FE3: ='Code_book_v3.3'!E126 -> NO | FF3: ='Code_book_v3.3'!H126 -> NO | FG3: ='Code_book_v3.3'!K126 -> NO | FH3: ='Code_book_v3.3'!K127 -> NO | FI3: ='Code_book_v3.3'!K128 -> NO | FJ3: ='Code_book_v3.3'!K129 -> NO | FK3: ='Code_book_v3.3'!N126 -> 0 | FL3: ='Code_book_v3.3'!H130 -> NO | FM3: ='Code_book_v3.3'!K130 -> NO | FN3: ='Code_book_v3.3'!K131 -> NO | FO3: ='Code_book_v3.3'!K132 -> NO | FP3: ='Code_book_v3.3'!K133 -> NO | FQ3: ='Code_book_v3.3'!N130 -> 0 | FR3: ='Code_book_v3.3'!H134 -> NO | FS3: ='Code_book_v3.3'!K134 -> NO | FT3: ='Code_book_v3.3'!K135 -> NO | FU3: ='Code_book_v3.3'!K136 -> NO | FV3: ='Code_book_v3.3'!K137 -> NO | FW3: ='Code_book_v3.3'!N134 -> 0 | FX3: ='Code_book_v3.3'!H138 -> NO | FY3: ='Code_book_v3.3'!K138 -> NO | FZ3: ='Code_book_v3.3'!K139 -> NO | GA3: ='Code_book_v3.3'!K140 -> NO | GB3: ='Code_book_v3.3'!K141 -> NO | GC3: ='Code_book_v3.3'!N138 -> 0 | GD3: ='Code_book_v3.3'!H142 -> NO | GE3: ='Code_book_v3.3'!K142 -> NO | GF3: ='Code_book_v3.3'!K143 -> NO | GG3: ='Code_book_v3.3'!K144 -> NO | GH3: ='Code_book_v3.3'!K145 -> NO | GI3: ='Code_book_v3.3'!N142 -> 0 | GJ3: ='Code_book_v3.3'!H146 -> NO | GK3: ='Code_book_v3.3'!K146 -> 0 | GL3: ='Code_book_v3.3'!E149 -> NO | GM3: ='Code_book_v3.3'!H149 -> NO | GN3: ='Code_book_v3.3'!H150 -> NO | GO3: ='Code_book_v3.3'!H151 -> NO | GP3: ='Code_book_v3.3'!H152 -> NO | GQ3: ='Code_book_v3.3'!H153 -> NO | GR3: ='Code_book_v3.3'!H154 -> NO | GS3: ='Code_book_v3.3'!K154 -> 0 | GT3: ='Code_book_v3.3'!E157 -> NO | GU3: ='Code_book_v3.3'!H157 -> 0
A8: NOTES: This summary table will be used for data extraction. Each public health guidance will have 1 row (filled out). These fields should automatically sync with the worksheet as you extract. Make sure to copy and paste the row onto the data_extraction_results sheet to ensure your individual extractions are saved. This page is locked to ensure data structure does not get altered. Password is wildfire to unlock

Sheet S_data_extraction
A2: doc_id | B2: source_name | C2: include_wfs_health_action | D2: use_air_cleaner | E2: use_HEPA_filter | F2: run_HVAC_continuous | G2: filter_air_vehicle | H2: run_HVAC_filter_specified | I2: run_HVAC_filter_type_txt | J2: reduce_outdoor_exercise | K2: stay_indoors | L2: stay_indoors_doors_windows_closed | M2: wear_mask | N2: wear_mask_N95 | O2: wear_mask_KN95 | P2: wear_mask_respirator | Q2: wear_mask_surgical | R2: wear_mask_against_specified | S2: wear_mask_against_txt | T2: wear_mask_other | U2: wear_mask_other_txt | V2: check_air_quality | W2: check_outdoor_AQ | X2: check_outdoor_AQ_method | Y2: check_outdoor_AQ_govt | Z2: check_outdoor_AQ_govt_ECCC | AA2: check_outdoor_AQ_govt_BC | AB2: check_outdoor_AQ_govt_FireSmoke | AC2: check_outdoor_AQ_crowdsource | AD2: check_outdoor_AQ_PurpleAir | AE2: check_outdoor_AQ_IQair | AF2: outdoor_AQ_action_specified | AG2: outdoor_AQ_action_txt | AH2: monitor_indoor_AQ | AI2: indoor_monitor_type_specified | AJ2: indoor_monitor_type_txt | AK2: indoor_monitor_action_specified | AL2: indoor_monitor_action_txt | AM2: other_health_action | AN2: other_health_action_txt | AO2: target_audience_present | AP2: target_audience_general_pop | AQ2: target_group_children_infants | AR2: target_group_older | AS2: target_group_pregnant | AT2: target_group_pregnant | AU2: target_group_current_lung_disease | AV2: target_group_current_other_health | AW2: target_group_current_other_health_txt | AX2: target_group_current_other | AY2: target_group_current_other_txt | AZ2: guidance_goal_present | BA2: guidance_goal_protect_health_general | BB2: guidance_goal_protect_lung_health | BC2: guidance_goal_protect_health_other | BD2: guidance_goal_protect_health_other_txt | BE2: guidance_goal_informs_decisions | BF2: guidance_goal_other | BG2: guidance_goal_other_txt | BH2: author_individual_level | BI2: author_names_present | BJ2: author_accreditation_present | BK2: author_additional_info_present | BL2: author_additional_info_txt | BM2: dev_process_described | BN2: dev_process_details_txt | BO2: multi_language_available | BP2: language_french | BQ2: language_chinese | BR2: language_hindi | BS2: language_punjabi | BT2: language_spanish | BU2: language_other_specified | BV2: language_other_txt | BW2: benefits_present | BX2: benefits_hepa | BY2: benefits_HEPA_improves_air_quality | BZ2: benefits_HEPA_improves_lung_health | CA2: benefits_HEPA_improves_other_health | CB2: benefits_HEPA_improves_other_non_health | CC2: benefits_DIY | CD2: benefits_DIY_improves_air_quality | CE2: benefits_DIY_improves_lung_health | CF2: benefits_DIY_improves_other_health | CG2: benefits_DIY_improves_other_non_health | CH2: benefits_indoor | CI2: benefits_indoor_improves_air_quality | CJ2: benefits_indoor_improves_lung_health | CK2: benefits_indoor_improves_other_health | CL2: benefits_indoor_improves_other_non_health | CM2: benefits_reduce_outdoor | CN2: bruden_present | CO2: burden_hepa | CP2: burden_HEPA_upfront_cost | CQ2: burden_HEPA_main_cost | CR2: burden_HEPA_noise | CS2: burden_HEPA_other | CT2: burden_diy | CU2: burden_diy_main_cost | CV2: burden_diy_noise | CW2: burden_diy_other | CX2: burden_indoor | CY2: burden_indoor_work | CZ2: burden_indoor_well_being | DA2: burden_indoor_other | DB2: burden_outdoor | DC2: burden_outdoor_work | DD2: burden_outdoor_well_being | DE2: burden_outdoor_other | DF2: burden_mask | DG2: burden_mask_work | DH2: burden_mask_well_being | DI2: burden_mask_cost | DJ2: burden_mask_other | DK2: burden_other | DL2: burden_other_txt | DM2: effectsize_present | DN2: effectsize_HEPA_present | DO2: effectsize_HEPA_air_quality | DP2: effectsize_HEPA_lung_health | DQ2: effectsize_HEPA_other_health | DR2: effectsize_HEPA_other | DS2: effectsize_HEPA_txt | DT2: effectsize_DIY_present | DU2: effectsize_DIY_air_quality | DV2: effectsize_DIY_lung_health | DW2: effectsize_DIY_other_health | DX2: effectsize_DIY_other | DY2: effectsize_DIY_txt | DZ2: effectsize_stay_indoors_present | EA2: effectsize_stay_indoors_reduce_exposure | EB2: effectsize_stay_indoors_lung_health | EC2: effectsize_stay_indoors_other_health | ED2: effectsize_stay_indoors_other | EE2: effectsize_stay_indoors_txt | EF2: effectsize_reduce_exercise_present | EG2: effectsize_reduce_exercise_reduce_exposure | EH2: effectsize_reduce_exercise_lung_health | EI2: effectsize_reduce_exercise_other_health | EJ2: effectsize_reduce_exercise_other | EK2: effectsize_reduce_exercise_txt | EL2: effectsize_mask_present | EM2: effectsize_mask_reduce_exposure | EN2: effectsize_mask_lung_health | EO2: effectsize_mask_other_health | EP2: effectsize_mask_other | EQ2: effectsize_mask_txt | ER2: effectsize_other_action_present | ES2: effectsize_other_action_txt | ET2: effectsize_burden_present | EU2: effectsize_burden_HEPA_present | EV2: effectsize_burden_HEPA_air_quality | EW2: effectsize_burden_HEPA_lung_health | EX2: effectsize_burden_HEPA_other_health | EY2: effectsize_burden_HEPA_other | EZ2: effectsize_burden_HEPA_txt | FA2: effectsize_burden_DIY_present | FB2: effectsize_burden_DIY_air_quality | FC2: effectsize_burden_DIY_lung_health | FD2: effectsize_burden_DIY_other_health | FE2: effectsize_burden_DIY_other | FF2: effectsize_burden_DIY_txt | FG2: effectsize_burden_stay_indoors_present | FH2: effectsize_burden_stay_indoors_reduce_exposure | FI2: effectsize_burden_stay_indoors_lung_health | FJ2: effectsize_burden_stay_indoors_other_health | FK2: effectsize_burden_stay_indoors_other | FL2: effectsize_burden_stay_indoors_txt | FM2: effectsize_burden_reduce_exercise_present | FN2: effectsize_burden_reduce_exercise_reduce_exposure | FO2: effectsize_burden_reduce_exercise_lung_health | FP2: effectsize_burden_reduce_exercise_other_health | FQ2: effectsize_burden_reduce_exercise_other | FR2: effectsize_burden_reduce_exercise_txt | FS2: effectsize_burden_mask_present | FT2: effectsize_burden_mask_reduce_exposure | FU2: effectsize_burden_mask_lung_health | FV2: effectsize_burden_mask_other_health | FW2: effectsize_burden_mask_other | FX2: effectsize_burden_mask_txt | FY2: effectsize_burden_other_action_present | FZ2: effectsize_burden_other_action_txt | GA2: evidence_quality_present | GB2: evidence_quality_HEPA | GC2: evidence_quality_DIY | GD2: evidence_quality_stay_indoors | GE2: evidence_quality_reduce_exercise | GF2: evidence_quality_mask | GG2: evidence_quality_other | GH2: evidence_quality_other_action_txt | GI2: references_scientific_publications | GJ2: references_scientific_publications_txt
A3: vch_001 | B3: 2022 | C3: YES | D3: YES | E3: YES | F3: NO | G3: NO | H3: NO | I3: N/A | J3: YES | K3: YES | L3: YES | M3: NO | N3: NO | O3: NO | P3: NO | Q3: NO | R3: NO | S3: N/A | T3: NO | U3: N/A | V3: YES | W3: YES | X3: NO | Y3: NO | Z3: NO | AA3: NO | AB3: NO | AC3: NO | AD3: NO | AE3: NO | AF3: NO | AG3: N/A | AH3: NO | AI3: NO | AJ3: N/A | AK3: NO | AL3: N/A | AM3: YES | AN3: hydrate | AO3: NO | AP3: NO | AQ3: NO | AR3: NO | AS3: NO | AT3: NO | AU3: NO | AV3: NO | AW3: N/A | AX3: NO | AY3: N/A | AZ3: NO | BA3: NO | BB3: NO | BC3: NO | BD3: N/A | BE3: NO | BF3: NO | BG3: N/A | BH3: NO | BI3: NO | BJ3: NO | BK3: NO | BL3: N/A | BM3: NO | BN3: N/A | BO3: NO | BP3: NO | BQ3: NO | BR3: NO | BS3: NO | BT3: NO | BU3: NO | BV3: N/A | BW3: NO | BX3: NO | BY3: NO | BZ3: NO | CA3: NO | CB3: NO | CC3: NO | CD3: NO | CE3: NO | CF3: NO | CG3: NO | CH3: NO | CI3: NO | CJ3: NO | CK3: NO | CL3: NO | CM3: NO | CN3: NO | CO3: NO | CP3: NO | CQ3: NO | CR3: NO | CS3: NO | CT3: NO | CU3: NO | CV3: NO | CW3: NO | CX3: YES | CY3: NO | CZ3: NO | DA3: YES | DB3: NO | DC3: NO | DD3: NO | DE3: NO | DF3: NO | DG3: NO | DH3: NO | DI3: NO | DJ3: NO | DK3: NO | DL3: N/A | DM3: NO | DN3: NO | DO3: NO | DP3: NO | DQ3: NO | DR3: NO | DS3: N/A | DT3: NO | DU3: NO | DV3: NO | DW3: NO | DX3: NO | DY3: N/A | DZ3: NO | EA3: NO | EB3: NO | EC3: NO | ED3: NO | EE3: N/A | EF3: NO | EG3: NO | EH3: NO | EI3: NO | EJ3: NO | EK3: N/A | EL3: NO | EM3: NO | EN3: NO | EO3: NO | EP3: NO | EQ3: N/A | ER3: NO | ES3: N/A | ET3: NO | EU3: NO | EV3: NO | EW3: NO | EX3: NO | EY3: NO | EZ3: N/A | FA3: NO | FB3: NO | FC3: NO | FD3: NO | FE3: NO | FF3: N/A | FG3: NO | FH3: NO | FI3: NO | FJ3: NO | FK3: NO | FL3: N/A | FM3: NO | FN3: NO | FO3: NO | FP3: NO | FQ3: NO | FR3: N/A | FS3: NO | FT3: NO | FU3: NO | FV3: NO | FW3: NO | FX3: N/A | FY3: NO | FZ3: N/A | GA3: NO | GB3: NO | GC3: NO | GD3: NO | GE3: NO | GF3: NO | GG3: NO | GH3: N/A | GI3: NO | GJ3: N/A
A4: vch_002 | B4: 2024 | C4: YES | D4: YES | E4: YES | F4: NO | G4: NO | H4: YES | I4: MERV13 | J4: YES | K4: YES | L4: YES | M4: NO | N4: NO | O4: NO | P4: NO | Q4: NO | R4: NO | S4: N/A | T4: NO | U4: N/A | V4: YES | W4: YES | X4: YES | Y4: YES | Z4: NO | AA4: YES | AB4: NO | AC4: YES | AD4: NO | AE4: NO | AF4: YES | AG4: varies | AH4: YES | AI4: NO | AJ4: N/A | AK4: NO | AL4: N/A | AM4: YES | AN4: hydrate | AO4: NO | AP4: NO | AQ4: NO | AR4: NO | AS4: NO | AT4: NO | AU4: NO | AV4: NO | AW4: N/A | AX4: NO | AY4: N/A | AZ4: NO | BA4: NO | BB4: NO | BC4: NO | BD4: N/A | BE4: NO | BF4: NO | BG4: N/A | BH4: NO | BI4: NO | BJ4: NO | BK4: NO | BL4: N/A | BM4: NO | BN4: N/A | BO4: NO | BP4: NO | BQ4: NO | BR4: NO | BS4: NO | BT4: NO | BU4: NO | BV4: N/A | BW4: YES | BX4: YES | BY4: NO | BZ4: NO | CA4: NO | CB4: YES | CC4: NO | CD4: NO | CE4: NO | CF4: NO | CG4: NO | CH4: YES | CI4: YES | CJ4: NO | CK4: NO | CL4: NO | CM4: NO | CN4: YES | CO4: NO | CP4: NO | CQ4: NO | CR4: NO | CS4: NO | CT4: NO | CU4: NO | CV4: NO | CW4: NO | CX4: YES | CY4: NO | CZ4: NO | DA4: YES | DB4: NO | DC4: NO | DD4: NO | DE4: NO | DF4: NO | DG4: NO | DH4: NO | DI4: NO | DJ4: NO | DK4: NO | DL4: N/A | DM4: NO | DN4: NO | DO4: NO | DP4: NO | DQ4: NO | DR4: NO | DS4: N/A | DT4: NO | DU4: NO | DV4: NO | DW4: NO | DX4: NO | DY4: N/A | DZ4: NO | EA4: NO | EB4: NO | EC4: NO | ED4: NO | EE4: N/A | EF4: NO | EG4: NO | EH4: NO | EI4: NO | EJ4: NO | EK4: N/A | EL4: NO | EM4: NO | EN4: NO | EO4: NO | EP4: NO | EQ4: N/A | ER4: NO | ES4: N/A | ET4: NO | EU4: NO | EV4: NO | EW4: NO | EX4: NO | EY4: NO | EZ4: N/A | FA4: NO | FB4: NO | FC4: NO | FD4: NO | FE4: NO | FF4: N/A | FG4: NO | FH4: NO | FI4: NO | FJ4: NO | FK4: NO | FL4: N/A | FM4: NO | FN4: NO | FO4: NO | FP4: NO | FQ4: NO | FR4: N/A | FS4: NO | FT4: NO | FU4: NO | FV4: NO | FW4: NO | FX4: N/A | FY4: NO | FZ4: N/A | GA4: NO | GB4: NO | GC4: NO | GD4: NO | GE4: NO | GF4: NO | GG4: NO | GH4: N/A | GI4: NO | GJ4: N/A
A5: vch_004 | B5: 2024 | C5: YES | D5: YES | E5: YES | F5: YES | G5: NO | H5: YES | I5: MERV13, MERV16+, HEPA | J5: YES | K5: YES | L5: YES | M5: NO | N5: NO | O5: NO | P5: NO | Q5: NO | R5: NO | S5: N/A | T5: NO | U5: N/A | V5: YES | W5: YES | X5: YES | Y5: YES | Z5: NO | AA5: YES | AB5: NO | AC5: YES | AD5: NO | AE5: NO | AF5: YES | AG5: varies | AH5: YES | AI5: NO | AJ5: N/A | AK5: NO | AL5: N/A | AM5: YES | AN5: hydrate; reduce outdoor excercies | AO5: NO | AP5: NO | AQ5: NO | AR5: NO | AS5: NO | AT5: NO | AU5: NO | AV5: NO | AW5: N/A | AX5: NO | AY5: N/A | AZ5: NO | BA5: NO | BB5: NO | BC5: NO | BD5: N/A | BE5: NO | BF5: NO | BG5: N/A | BH5: NO | BI5: NO | BJ5: NO | BK5: NO | BL5: N/A | BM5: NO | BN5: N/A | BO5: NO | BP5: NO | BQ5: NO | BR5: NO | BS5: NO | BT5: NO | BU5: NO | BV5: N/A | BW5: YES | BX5: YES | BY5: NO | BZ5: NO | CA5: NO | CB5: YES | CC5: YES | CD5: YES | CE5: NO | CF5: NO | CG5: YES | CH5: YES | CI5: YES | CJ5: NO | CK5: NO | CL5: NO | CM5: YES | CN5: YES | CO5: YES | CP5: NO | CQ5: NO | CR5: NO | CS5: YES | CT5: NO | CU5: NO | CV5: NO | CW5: NO | CX5: YES | CY5: NO | CZ5: NO | DA5: YES | DB5: NO | DC5: NO | DD5: NO | DE5: NO | DF5: NO | DG5: NO | DH5: NO | DI5: NO | DJ5: NO | DK5: NO | DL5: N/A | DM5: NO | DN5: NO | DO5: NO | DP5: NO | DQ5: NO | DR5: NO | DS5: N/A | DT5: NO | DU5: NO | DV5: NO | DW5: NO | DX5: NO | DY5: N/A | DZ5: NO | EA5: NO | EB5: NO | EC5: NO | ED5: NO | EE5: N/A | EF5: NO | EG5: NO | EH5: NO | EI5: NO | EJ5: NO | EK5: N/A | EL5: NO | EM5: NO | EN5: NO | EO5: NO | EP5: NO | EQ5: N/A | ER5: NO | ES5: N/A | ET5: NO | EU5: NO | EV5: NO | EW5: NO | EX5: NO | EY5: NO | EZ5: N/A | FA5: NO | FB5: NO | FC5: NO | FD5: NO | FE5: NO | FF5: N/A | FG5: NO | FH5: NO | FI5: NO | FJ5: NO | FK5: NO | FL5: N/A | FM5: NO | FN5: NO | FO5: NO | FP5: NO | FQ5: NO | FR5: N/A | FS5: NO | FT5: NO | FU5: NO | FV5: NO | FW5: NO | FX5: N/A | FY5: NO | FZ5: N/A | GA5: NO | GB5: NO | GC5: NO | GD5: NO | GE5: NO | GF5: NO | GG5: NO | GH5: N/A | GI5: NO | GJ5: N/A
A6: vch_005 | B6: 2024 | C6: YES | D6: YES | E6: YES | F6: NO | G6: NO | H6: NO | I6: N/A | J6: NO | K6: NO | L6: NO | M6: NO | N6: NO | O6: NO | P6: NO | Q6: NO | R6: NO | S6: N/A | T6: NO | U6: N/A | V6: NO | W6: NO | X6: NO | Y6: NO | Z6: NO | AA6: NO | AB6: NO | AC6: NO | AD6: NO | AE6: NO | AF6: NO | AG6: N/A | AH6: YES | AI6: NO | AJ6: N/A | AK6: NO | AL6: N/A | AM6: YES | AN6: Wildfire Smoke Readiness Plan | AO6: NO | AP6: NO | AQ6: NO | AR6: NO | AS6: NO | AT6: NO | AU6: NO | AV6: NO | AW6: N/A | AX6: NO | AY6: N/A | AZ6: NO | BA6: NO | BB6: NO | BC6: NO | BD6: N/A | BE6: NO | BF6: NO | BG6: N/A | BH6: NO | BI6: NO | BJ6: NO | BK6: NO | BL6: N/A | BM6: NO | BN6: N/A | BO6: NO | BP6: NO | BQ6: NO | BR6: NO | BS6: NO | BT6: NO | BU6: NO | BV6: N/A | BW6: YES | BX6: NO | BY6: YES | BZ6: NO | CA6: NO | CB6: NO | CC6: YES | CD6: NO | CE6: NO | CF6: NO | CG6: YES | CH6: NO | CI6: NO | CJ6: NO | CK6: NO | CL6: NO | CM6: NO | CN6: YES | CO6: YES | CP6: NO | CQ6: NO | CR6: YES | CS6: YES | CT6: NO | CU6: NO | CV6: NO | CW6: NO | CX6: YES | CY6: NO | CZ6: NO | DA6: NO | DB6: NO | DC6: NO | DD6: NO | DE6: NO | DF6: NO | DG6: NO | DH6: NO | DI6: NO | DJ6: NO | DK6: NO | DL6: N/A | DM6: NO | DN6: NO | DO6: NO | DP6: NO | DQ6: NO | DR6: NO | DS6: N/A | DT6: NO | DU6: NO | DV6: NO | DW6: NO | DX6: NO | DY6: N/A | DZ6: NO | EA6: NO | EB6: NO | EC6: NO | ED6: NO | EE6: N/A | EF6: NO | EG6: NO | EH6: NO | EI6: NO | EJ6: NO | EK6: N/A | EL6: NO | EM6: NO | EN6: NO | EO6: NO | EP6: NO | EQ6: N/A | ER6: NO | ES6: N/A | ET6: NO | EU6: NO | EV6: NO | EW6: NO | EX6: NO | EY6: NO | EZ6: N/A | FA6: NO | FB6: NO | FC6: NO | FD6: NO | FE6: NO | FF6: N/A | FG6: NO | FH6: NO | FI6: NO | FJ6: NO | FK6: NO | FL6: N/A | FM6: NO | FN6: NO | FO6: NO | FP6: NO | FQ6: NO | FR6: N/A | FS6: NO | FT6: NO | FU6: NO | FV6: NO | FW6: NO | FX6: N/A | FY6: NO | FZ6: N/A | GA6: NO | GB6: NO | GC6: NO | GD6: NO | GE6: NO | GF6: NO | GG6: NO | GH6: N/A | GI6: NO | GJ6: N/A
A7: vch_006 | B7: N/A | C7: YES | D7: NO | E7: NO | F7: NO | G7: NO | H7: NO | I7: N/A | J7: YES | K7: YES | L7: YES | M7: NO | N7: NO | O7: NO | P7: NO | Q7: NO | R7: NO | S7: N/A | T7: NO | U7: N/A | V7: NO | W7: NO | X7: NO | Y7: NO | Z7: NO | AA7: NO | AB7: NO | AC7: NO | AD7: NO | AE7: NO | AF7: NO | AG7: N/A | AH7: NO | AI7: NO | AJ7: N/A | AK7: NO | AL7: N/A | AM7: NO | AN7: N/A | AO7: YES | AP7: NO | AQ7: YES | AR7: NO | AS7: NO | AT7: NO | AU7: NO | AV7: NO | AW7: N/A | AX7: NO | AY7: N/A | AZ7: NO | BA7: NO | BB7: NO | BC7: NO | BD7: N/A | BE7: NO | BF7: NO | BG7: N/A | BH7: NO | BI7: NO | BJ7: NO | BK7: NO | BL7: N/A | BM7: NO | BN7: N/A | BO7: NO | BP7: NO | BQ7: NO | BR7: NO | BS7: NO | BT7: NO | BU7: NO | BV7: N/A | BW7: NO | BX7: NO | BY7: NO | BZ7: NO | CA7: NO | CB7: NO | CC7: NO | CD7: NO | CE7: NO | CF7: NO | CG7: NO | CH7: NO | CI7: NO | CJ7: NO | CK7: NO | CL7: NO | CM7: NO | CN7: NO | CO7: NO | CP7: NO | CQ7: NO | CR7: NO | CS7: NO | CT7: NO | CU7: NO | CV7: NO | CW7: NO | CX7: NO | CY7: NO | CZ7: NO | DA7: NO | DB7: NO | DC7: NO | DD7: NO | DE7: NO | DF7: NO | DG7: NO | DH7: NO | DI7: NO | DJ7: NO | DK7: NO | DL7: N/A | DM7: NO | DN7: NO | DO7: NO | DP7: NO | DQ7: NO | DR7: NO | DS7: N/A | DT7: NO | DU7: NO | DV7: NO | DW7: NO | DX7: NO | DY7: N/A | DZ7: NO | EA7: NO | EB7: NO | EC7: NO | ED7: NO | EE7: N/A | EF7: NO | EG7: NO | EH7: NO | EI7: NO | EJ7: NO | EK7: N/A | EL7: NO | EM7: NO | EN7: NO | EO7: NO | EP7: NO | EQ7: N/A | ER7: NO | ES7: N/A | ET7: NO | EU7: NO | EV7: NO | EW7: NO | EX7: NO | EY7: NO | EZ7: N/A | FA7: NO | FB7: NO | FC7: NO | FD7: NO | FE7: NO | FF7: N/A | FG7: NO | FH7: NO | FI7: NO | FJ7: NO | FK7: NO | FL7: N/A | FM7: NO | FN7: NO | FO7: NO | FP7: NO | FQ7: NO | FR7: N/A | FS7: NO | FT7: NO | FU7: NO | FV7: NO | FW7: NO | FX7: N/A | FY7: NO | FZ7: N/A | GA7: NO | GB7: NO | GC7: NO | GD7: NO | GE7: NO | GF7: NO | GG7: NO | GH7: N/A | GI7: NO | GJ7: N/A
A8: vch_007 | B8: N/A | C8: YES | D8: NO | E8: NO | F8: NO | G8: NO | H8: NO | I8: N/A | J8: YES | K8: YES | L8: NO | M8: NO | N8: NO | O8: NO | P8: NO | Q8: NO | R8: NO | S8: N/A | T8: NO | U8: N/A | V8: YES | W8: NO | X8: NO | Y8: NO | Z8: NO | AA8: NO | AB8: NO | AC8: NO | AD8: NO | AE8: NO | AF8: NO | AG8: N/A | AH8: NO | AI8: NO | AJ8: N/A | AK8: NO | AL8: N/A | AM8: YES | AN8: asthma treatment plan and rescue medications | AO8: YES | AP8: NO | AQ8: YES | AR8: NO | AS8: NO | AT8: NO | AU8: NO | AV8: NO | AW8: N/A | AX8: NO | AY8: N/A | AZ8: NO | BA8: NO | BB8: NO | BC8: NO | BD8: N/A | BE8: NO | BF8: NO | BG8: N/A | BH8: NO | BI8: NO | BJ8: NO | BK8: NO | BL8: N/A | BM8: NO | BN8: N/A | BO8: NO | BP8: NO | BQ8: NO | BR8: NO | BS8: NO | BT8: NO | BU8: NO | BV8: N/A | BW8: NO | BX8: NO | BY8: NO | BZ8: NO | CA8: NO | CB8: NO | CC8: NO | CD8: NO | CE8: NO | CF8: NO | CG8: NO | CH8: YES | CI8: YES | CJ8: NO | CK8: NO | CL8: NO | CM8: NO | CN8: NO | CO8: NO | CP8: NO | CQ8: NO | CR8: NO | CS8: NO | CT8: NO | CU8: NO | CV8: NO | CW8: NO | CX8: NO | CY8: NO | CZ8: NO | DA8: NO | DB8: NO | DC8: NO | DD8: NO | DE8: NO | DF8: NO | DG8: NO | DH8: NO | DI8: NO | DJ8: NO | DK8: NO | DL8: N/A | DM8: NO | DN8: NO | DO8: NO | DP8: NO | DQ8: NO | DR8: NO | DS8: N/A | DT8: NO | DU8: NO | DV8: NO | DW8: NO | DX8: NO | DY8: N/A | DZ8: NO | EA8: NO | EB8: NO | EC8: NO | ED8: NO | EE8: N/A | EF8: NO | EG8: NO | EH8: NO | EI8: NO | EJ8: NO | EK8: N/A | EL8: NO | EM8: NO | EN8: NO | EO8: NO | EP8: NO | EQ8: N/A | ER8: NO | ES8: N/A | ET8: NO | EU8: NO | EV8: NO | EW8: NO | EX8: NO | EY8: NO | EZ8: N/A | FA8: NO | FB8: NO | FC8: NO | FD8: NO | FE8: NO | FF8: N/A | FG8: NO | FH8: NO | FI8: NO | FJ8: NO | FK8: NO | FL8: N/A | FM8: NO | FN8: NO | FO8: NO | FP8: NO | FQ8: NO | FR8: N/A | FS8: NO | FT8: NO | FU8: NO | FV8: NO | FW8: NO | FX8: N/A | FY8: NO | FZ8: N/A | GA8: NO | GB8: NO | GC8: NO | GD8: NO | GE8: NO | GF8: NO | GG8: NO | GH8: N/A | GI8: NO | GJ8: N/A
A9: vch_008 | B9: N/A | C9: YES | D9: NO | E9: NO | F9: NO | G9: NO | H9: NO | I9: N/A | J9: YES | K9: YES | L9: NO | M9: NO | N9: NO | O9: NO | P9: NO | Q9: NO | R9: NO | S9: N/A | T9: NO | U9: N/A | V9: NO | W9: NO | X9: NO | Y9: NO | Z9: NO | AA9: NO | AB9: NO | AC9: NO | AD9: NO | AE9: NO | AF9: NO | AG9: N/A | AH9: NO | AI9: NO | AJ9: N/A | AK9: NO | AL9: N/A | AM9: NO | AN9: N/A | AO9: NO | AP9: NO | AQ9: NO | AR9: NO | AS9: YES | AT9: YES | AU9: NO | AV9: NO | AW9: N/A | AX9: NO | AY9: N/A | AZ9: NO | BA9: NO | BB9: NO | BC9: NO | BD9: N/A | BE9: NO | BF9: NO | BG9: N/A | BH9: NO | BI9: NO | BJ9: NO | BK9: NO | BL9: N/A | BM9: NO | BN9: N/A | BO9: NO | BP9: NO | BQ9: NO | BR9: NO | BS9: NO | BT9: NO | BU9: NO | BV9: N/A | BW9: NO | BX9: NO | BY9: NO | BZ9: NO | CA9: NO | CB9: NO | CC9: NO | CD9: NO | CE9: NO | CF9: NO | CG9: NO | CH9: NO | CI9: NO | CJ9: NO | CK9: NO | CL9: NO | CM9: NO | CN9: NO | CO9: NO | CP9: NO | CQ9: NO | CR9: NO | CS9: NO | CT9: NO | CU9: NO | CV9: NO | CW9: NO | CX9: NO | CY9: NO | CZ9: NO | DA9: NO | DB9: NO | DC9: NO | DD9: NO | DE9: NO | DF9: NO | DG9: NO | DH9: NO | DI9: NO | DJ9: NO | DK9: NO | DL9: N/A | DM9: NO | DN9: NO | DO9: NO | DP9: NO | DQ9: NO | DR9: NO | DS9: N/A | DT9: NO | DU9: NO | DV9: NO | DW9: NO | DX9: NO | DY9: N/A | DZ9: NO | EA9: NO | EB9: NO | EC9: NO | ED9: NO | EE9: N/A | EF9: NO | EG9: NO | EH9: NO | EI9: NO | EJ9: NO | EK9: N/A | EL9: NO | EM9: NO | EN9: NO | EO9: NO | EP9: NO | EQ9: N/A | ER9: NO | ES9: N/A | ET9: NO | EU9: NO | EV9: NO | EW9: NO | EX9: NO | EY9: NO | EZ9: N/A | FA9: NO | FB9: NO | FC9: NO | FD9: NO | FE9: NO | FF9: N/A | FG9: NO | FH9: NO | FI9: NO | FJ9: NO | FK9: NO | FL9: N/A | FM9: NO | FN9: NO | FO9: NO | FP9: NO | FQ9: NO | FR9: N/A | FS9: NO | FT9: NO | FU9: NO | FV9: NO | FW9: NO | FX9: N/A | FY9: NO | FZ9: N/A | GA9: NO | GB9: NO | GC9: NO | GD9: NO | GE9: NO | GF9: NO | GG9: NO | GH9: N/A | GI9: NO | GJ9: N/A
A10: vch_009 | B10: N/A | C10: YES | D10: NO | E10: NO | F10: NO | G10: NO | H10: NO | I10: N/A | J10: YES | K10: YES | L10: NO | M10: NO | N10: NO | O10: NO | P10: NO | Q10: NO | R10: NO | S10: N/A | T10: NO | U10: N/A | V10: YES | W10: YES | X10: YES | Y10: NO | Z10: NO | AA10: NO | AB10: NO | AC10: NO | AD10: NO | AE10: NO | AF10: NO | AG10: N/A | AH10: NO | AI10: NO | AJ10: N/A | AK10: NO | AL10: N/A | AM10: NO | AN10: asthma treatment plan and rescue medications | AO10: YES | AP10: NO | AQ10: NO | AR10: NO | AS10: YES | AT10: YES | AU10: NO | AV10: NO | AW10: N/A | AX10: NO | AY10: N/A | AZ10: NO | BA10: NO | BB10: NO | BC10: NO | BD10: N/A | BE10: NO | BF10: NO | BG10: N/A | BH10: NO | BI10: NO | BJ10: NO | BK10: NO | BL10: N/A | BM10: NO | BN10: N/A | BO10: NO | BP10: NO | BQ10: NO | BR10: NO | BS10: NO | BT10: NO | BU10: NO | BV10: N/A | BW10: NO | BX10: NO | BY10: NO | BZ10: NO | CA10: NO | CB10: NO | CC10: NO | CD10: NO | CE10: NO | CF10: NO | CG10: NO | CH10: YES | CI10: YES | CJ10: NO | CK10: NO | CL10: NO | CM10: NO | CN10: NO | CO10: NO | CP10: NO | CQ10: NO | CR10: NO | CS10: NO | CT10: NO | CU10: NO | CV10: NO | CW10: NO | CX10: NO | CY10: NO | CZ10: NO | DA10: NO | DB10: NO | DC10: NO | DD10: NO | DE10: NO | DF10: NO | DG10: NO | DH10: NO | DI10: NO | DJ10: NO | DK10: NO | DL10: N/A | DM10: NO | DN10: NO | DO10: NO | DP10: NO | DQ10: NO | DR10: NO | DS10: N/A | DT10: NO | DU10: NO | DV10: NO | DW10: NO | DX10: NO | DY10: N/A | DZ10: NO | EA10: NO | EB10: NO | EC10: NO | ED10: NO | EE10: N/A | EF10: NO | EG10: NO | EH10: NO | EI10: NO | EJ10: NO | EK10: N/A | EL10: NO | EM10: NO | EN10: NO | EO10: NO | EP10: NO | EQ10: N/A | ER10: NO | ES10: N/A | ET10: NO | EU10: NO | EV10: NO | EW10: NO | EX10: NO | EY10: NO | EZ10: N/A | FA10: NO | FB10: NO | FC10: NO | FD10: NO | FE10: NO | FF10: N/A | FG10: NO | FH10: NO | FI10: NO | FJ10: NO | FK10: NO | FL10: N/A | FM10: NO | FN10: NO | FO10: NO | FP10: NO | FQ10: NO | FR10: N/A | FS10: NO | FT10: NO | FU10: NO | FV10: NO | FW10: NO | FX10: N/A | FY10: NO | FZ10: N/A | GA10: NO | GB10: NO | GC10: NO | GD10: NO | GE10: NO | GF10: NO | GG10: NO | GH10: N/A | GI10: NO | GJ10: N/A
A11: vch_011 | B11: 2024 | C11: YES | D11: YES | E11: NO | F11: NO | G11: NO | H11: NO | I11: N/A | J11: YES | K11: YES | L11: YES | M11: NO | N11: NO | O11: NO | P11: NO | Q11: NO | R11: NO | S11: N/A | T11: NO | U11: N/A | V11: YES | W11: YES | X11: YES | Y11: NO | Z11: NO | AA11: NO | AB11: NO | AC11: NO | AD11: NO | AE11: NO | AF11: NO | AG11: N/A | AH11: NO | AI11: NO | AJ11: N/A | AK11: NO | AL11: N/A | AM11: YES | AN11: seek air conditioned spaces (e.g., mall) | AO11: NO | AP11: NO | AQ11: NO | AR11: NO | AS11: NO | AT11: NO | AU11: NO | AV11: NO | AW11: N/A | AX11: NO | AY11: N/A | AZ11: NO | BA11: NO | BB11: NO | BC11: NO | BD11: N/A | BE11: NO | BF11: NO | BG11: N/A | BH11: NO | BI11: NO | BJ11: NO | BK11: NO | BL11: N/A | BM11: NO | BN11: N/A | BO11: NO | BP11: NO | BQ11: NO | BR11: NO | BS11: NO | BT11: NO | BU11: NO | BV11: N/A | BW11: NO | BX11: NO | BY11: NO | BZ11: NO | CA11: NO | CB11: NO | CC11: NO | CD11: NO | CE11: NO | CF11: NO | CG11: NO | CH11: NO | CI11: NO | CJ11: NO | CK11: NO | CL11: NO | CM11: NO | CN11: NO | CO11: NO | CP11: NO | CQ11: NO | CR11: NO | CS11: NO | CT11: NO | CU11: NO | CV11: NO | CW11: NO | CX11: NO | CY11: NO | CZ11: NO | DA11: NO | DB11: NO | DC11: NO | DD11: NO | DE11: NO | DF11: NO | DG11: NO | DH11: NO | DI11: NO | DJ11: NO | DK11: NO | DL11: N/A | DM11: NO | DN11: NO | DO11: NO | DP11: NO | DQ11: NO | DR11: NO | DS11: N/A | DT11: NO | DU11: NO | DV11: NO | DW11: NO | DX11: NO | DY11: N/A | DZ11: NO | EA11: NO | EB11: NO | EC11: NO | ED11: NO | EE11: N/A | EF11: NO | EG11: NO | EH11: NO | EI11: NO | EJ11: NO | EK11: N/A | EL11: NO | EM11: NO | EN11: NO | EO11: NO | EP11: NO | EQ11: N/A | ER11: NO | ES11: N/A | ET11: NO | EU11: NO | EV11: NO | EW11: NO | EX11: NO | EY11: NO | EZ11: N/A | FA11: NO | FB11: NO | FC11: NO | FD11: NO | FE11: NO | FF11: N/A | FG11: NO | FH11: NO | FI11: NO | FJ11: NO | FK11: NO | FL11: N/A | FM11: NO | FN11: NO | FO11: NO | FP11: NO | FQ11: NO | FR11: N/A | FS11: NO | FT11: NO | FU11: NO | FV11: NO | FW11: NO | FX11: N/A | FY11: NO | FZ11: N/A | GA11: NO | GB11: NO | GC11: NO | GD11: NO | GE11: NO | GF11: NO | GG11: NO | GH11: N/A | GI11: NO | GJ11: N/A
A12: vch_012 | B12: N/A | C12: YES | D12: NO | E12: NO | F12: NO | G12: NO | H12: NO | I12: N/A | J12: YES | K12: YES | L12: YES | M12: YES | N12: YES | O12: NO | P12: NO | Q12: NO | R12: NO | S12: N/A | T12: NO | U12: N/A | V12: YES | W12: YES | X12: YES | Y12: YES | Z12: NO | AA12: YES | AB12: NO | AC12: NO | AD12: NO | AE12: NO | AF12: YES | AG12: varies | AH12: NO | AI12: NO | AJ12: N/A | AK12: NO | AL12: N/A | AM12: NO | AN12: N/A | AO12: NO | AP12: NO | AQ12: NO | AR12: NO | AS12: NO | AT12: NO | AU12: NO | AV12: NO | AW12: N/A | AX12: NO | AY12: N/A | AZ12: NO | BA12: NO | BB12: NO | BC12: NO | BD12: N/A | BE12: NO | BF12: NO | BG12: N/A | BH12: NO | BI12: NO | BJ12: NO | BK12: NO | BL12: N/A | BM12: NO | BN12: N/A | BO12: NO | BP12: NO | BQ12: NO | BR12: NO | BS12: NO | BT12: NO | BU12: NO | BV12: N/A | BW12: YES | BX12: NO | BY12: NO | BZ12: NO | CA12: NO | CB12: NO | CC12: YES | CD12: YES | CE12: NO | CF12: NO | CG12: NO | CH12: YES | CI12: YES | CJ12: NO | CK12: NO | CL12: NO | CM12: YES | CN12: YES | CO12: NO | CP12: NO | CQ12: NO | CR12: NO | CS12: NO | CT12: NO | CU12: NO | CV12: NO | CW12: NO | CX12: YES | CY12: NO | CZ12: NO | DA12: YES | DB12: NO | DC12: NO | DD12: NO | DE12: NO | DF12: NO | DG12: NO | DH12: NO | DI12: NO | DJ12: NO | DK12: NO | DL12: N/A | DM12: NO | DN12: NO | DO12: NO | DP12: NO | DQ12: NO | DR12: NO | DS12: N/A | DT12: NO | DU12: NO | DV12: NO | DW12: NO | DX12: NO | DY12: N/A | DZ12: NO | EA12: NO | EB12: NO | EC12: NO | ED12: NO | EE12: N/A | EF12: NO | EG12: NO | EH12: NO | EI12: NO | EJ12: NO | EK12: N/A | EL12: NO | EM12: NO | EN12: NO | EO12: NO | EP12: NO | EQ12: N/A | ER12: NO | ES12: N/A | ET12: NO | EU12: NO | EV12: NO | EW12: NO | EX12: NO | EY12: NO | EZ12: N/A | FA12: NO | FB12: NO | FC12: NO | FD12: NO | FE12: NO | FF12: N/A | FG12: NO | FH12: NO | FI12: NO | FJ12: NO | FK12: NO | FL12: N/A | FM12: NO | FN12: NO | FO12: NO | FP12: NO | FQ12: NO | FR12: N/A | FS12: NO | FT12: NO | FU12: NO | FV12: NO | FW12: NO | FX12: N/A | FY12: NO | FZ12: N/A | GA12: NO | GB12: NO | GC12: NO | GD12: NO | GE12: NO | GF12: NO | GG12: NO | GH12: N/A | GI12: NO | GJ12: N/A
A13: vch_013 | B13: 2024 | C13: YES | D13: YES | E13: YES | F13: NO | G13: NO | H13: NO | I13: N/A | J13: YES | K13: YES | L13: YES | M13: YES | N13: YES | O13: NO | P13: NO | Q13: NO | R13: NO | S13: N/A | T13: NO | U13: N/A | V13: YES | W13: YES | X13: YES | Y13: YES | Z13: NO | AA13: NO | AB13: NO | AC13: NO | AD13: NO | AE13: NO | AF13: YES | AG13: varies | AH13: NO | AI13: NO | AJ13: N/A | AK13: NO | AL13: N/A | AM13: NO | AN13: N/A | AO13: NO | AP13: NO | AQ13: NO | AR13: NO | AS13: NO | AT13: NO | AU13: NO | AV13: NO | AW13: N/A | AX13: NO | AY13: N/A | AZ13: NO | BA13: NO | BB13: NO | BC13: NO | BD13: N/A | BE13: NO | BF13: NO | BG13: N/A | BH13: NO | BI13: NO | BJ13: NO | BK13: NO | BL13: N/A | BM13: NO | BN13: N/A | BO13: NO | BP13: NO | BQ13: NO | BR13: NO | BS13: NO | BT13: NO | BU13: NO | BV13: N/A | BW13: YES | BX13: NO | BY13: NO | BZ13: NO | CA13: NO | CB13: NO | CC13: YES | CD13: YES | CE13: NO | CF13: NO | CG13: NO | CH13: YES | CI13: YES | CJ13: NO | CK13: NO | CL13: NO | CM13: YES | CN13: YES | CO13: NO | CP13: NO | CQ13: NO | CR13: NO | CS13: NO | CT13: NO | CU13: NO | CV13: NO | CW13: NO | CX13: YES | CY13: NO | CZ13: NO | DA13: YES | DB13: NO | DC13: NO | DD13: NO | DE13: NO | DF13: NO | DG13: NO | DH13: NO | DI13: NO | DJ13: NO | DK13: NO | DL13: N/A | DM13: NO | DN13: NO | DO13: NO | DP13: NO | DQ13: NO | DR13: NO | DS13: N/A | DT13: NO | DU13: NO | DV13: NO | DW13: NO | DX13: NO | DY13: N/A | DZ13: NO | EA13: NO | EB13: NO | EC13: NO | ED13: NO | EE13: N/A | EF13: NO | EG13: NO | EH13: NO | EI13: NO | EJ13: NO | EK13: N/A | EL13: NO | EM13: NO | EN13: NO | EO13: NO | EP13: NO | EQ13: N/A | ER13: NO | ES13: N/A | ET13: NO | EU13: NO | EV13: NO | EW13: NO | EX13: NO | EY13: NO | EZ13: N/A | FA13: NO | FB13: NO | FC13: NO | FD13: NO | FE13: NO | FF13: N/A | FG13: NO | FH13: NO | FI13: NO | FJ13: NO | FK13: NO | FL13: N/A | FM13: NO | FN13: NO | FO13: NO | FP13: NO | FQ13: NO | FR13: N/A | FS13: NO | FT13: NO | FU13: NO | FV13: NO | FW13: NO | FX13: N/A | FY13: NO | FZ13: N/A | GA13: NO | GB13: NO | GC13: NO | GD13: NO | GE13: NO | GF13: NO | GG13: NO | GH13: N/A | GI13: NO | GJ13: N/A
A14: can_001 | B14: 2025 | C14: YES | D14: YES | E14: YES | F14: NO | G14: NO | H14: NO | I14: N/A | J14: NO | K14: NO | L14: YES | M14: NO | N14: NO | O14: NO | P14: NO | Q14: NO | R14: NO | S14: N/A | T14: NO | U14: N/A | V14: YES | W14: YES | X14: YES | Y14: YES | Z14: YES | AA14: NO | AB14: NO | AC14: NO | AD14: NO | AE14: NO | AF14: NO | AG14: N/A | AH14: NO | AI14: NO | AJ14: N/A | AK14: NO | AL14: N/A | AM14: NO | AN14: N/A | AO14: NO | AP14: NO | AQ14: NO | AR14: NO | AS14: NO | AT14: NO | AU14: NO | AV14: NO | AW14: N/A | AX14: NO | AY14: N/A | AZ14: NO | BA14: NO | BB14: NO | BC14: NO | BD14: N/A | BE14: NO | BF14: NO | BG14: N/A | BH14: NO | BI14: NO | BJ14: NO | BK14: NO | BL14: N/A | BM14: NO | BN14: N/A | BO14: NO | BP14: NO | BQ14: NO | BR14: NO | BS14: NO | BT14: NO | BU14: NO | BV14: N/A | BW14: NO | BX14: NO | BY14: NO | BZ14: NO | CA14: NO | CB14: NO | CC14: NO | CD14: NO | CE14: NO | CF14: NO | CG14: NO | CH14: NO | CI14: NO | CJ14: NO | CK14: NO | CL14: NO | CM14: YES | CN14: NO | CO14: NO | CP14: NO | CQ14: NO | CR14: NO | CS14: NO | CT14: NO | CU14: NO | CV14: NO | CW14: NO | CX14: NO | CY14: NO | CZ14: NO | DA14: NO | DB14: NO | DC14: NO | DD14: NO | DE14: NO | DF14: NO | DG14: NO | DH14: NO | DI14: NO | DJ14: NO | DK14: NO | DL14: N/A | DM14: NO | DN14: NO | DO14: NO | DP14: NO | DQ14: NO | DR14: NO | DS14: N/A | DT14: NO | DU14: NO | DV14: NO | DW14: NO | DX14: NO | DY14: N/A | DZ14: NO | EA14: NO | EB14: NO | EC14: NO | ED14: NO | EE14: N/A | EF14: NO | EG14: NO | EH14: NO | EI14: NO | EJ14: NO | EK14: N/A | EL14: NO | EM14: NO | EN14: NO | EO14: NO | EP14: NO | EQ14: N/A | ER14: NO | ES14: N/A | ET14: NO | EU14: NO | EV14: NO | EW14: NO | EX14: NO | EY14: NO | EZ14: N/A | FA14: NO | FB14: NO | FC14: NO | FD14: NO | FE14: NO | FF14: N/A | FG14: NO | FH14: NO | FI14: NO | FJ14: NO | FK14: NO | FL14: N/A | FM14: NO | FN14: NO | FO14: NO | FP14: NO | FQ14: NO | FR14: N/A | FS14: NO | FT14: NO | FU14: NO | FV14: NO | FW14: NO | FX14: N/A | FY14: NO | FZ14: N/A | GA14: NO | GB14: NO | GC14: NO | GD14: NO | GE14: NO | GF14: NO | GG14: NO | GH14: N/A | GI14: NO | GJ14: N/A
A15: can_002 | B15: 2024 | C15: YES | D15: YES | E15: NO | F15: NO | G15: NO | H15: NO | I15: N/A | J15: YES | K15: YES | L15: YES | M15: NO | N15: NO | O15: NO | P15: NO | Q15: NO | R15: NO | S15: N/A | T15: NO | U15: N/A | V15: YES | W15: YES | X15: YES | Y15: YES | Z15: YES | AA15: NO | AB15: NO | AC15: NO | AD15: NO | AE15: NO | AF15: NO | AG15: N/A | AH15: NO | AI15: NO | AJ15: N/A | AK15: NO | AL15: N/A | AM15: YES | AN15: take care of mental health | AO15: NO | AP15: NO | AQ15: NO | AR15: NO | AS15: NO | AT15: NO | AU15: NO | AV15: NO | AW15: N/A | AX15: NO | AY15: N/A | AZ15: NO | BA15: NO | BB15: NO | BC15: NO | BD15: N/A | BE15: NO | BF15: NO | BG15: N/A | BH15: NO | BI15: NO | BJ15: NO | BK15: NO | BL15: N/A | BM15: NO | BN15: N/A | BO15: NO | BP15: NO | BQ15: NO | BR15: NO | BS15: NO | BT15: NO | BU15: NO | BV15: N/A | BW15: YES | BX15: NO | BY15: NO | BZ15: NO | CA15: NO | CB15: NO | CC15: NO | CD15: NO | CE15: NO | CF15: NO | CG15: NO | CH15: YES | CI15: YES | CJ15: NO | CK15: NO | CL15: NO | CM15: YES | CN15: YES | CO15: NO | CP15: NO | CQ15: NO | CR15: NO | CS15: NO | CT15: NO | CU15: NO | CV15: NO | CW15: NO | CX15: YES | CY15: NO | CZ15: NO | DA15: YES | DB15: NO | DC15: NO | DD15: NO | DE15: NO | DF15: NO | DG15: NO | DH15: NO | DI15: NO | DJ15: NO | DK15: NO | DL15: N/A | DM15: NO | DN15: NO | DO15: NO | DP15: NO | DQ15: NO | DR15: NO | DS15: N/A | DT15: NO | DU15: NO | DV15: NO | DW15: NO | DX15: NO | DY15: N/A | DZ15: NO | EA15: NO | EB15: NO | EC15: NO | ED15: NO | EE15: N/A | EF15: NO | EG15: NO | EH15: NO | EI15: NO | EJ15: NO | EK15: N/A | EL15: NO | EM15: NO | EN15: NO | EO15: NO | EP15: NO | EQ15: N/A | ER15: NO | ES15: N/A | ET15: NO | EU15: NO | EV15: NO | EW15: NO | EX15: NO | EY15: NO | EZ15: N/A | FA15: NO | FB15: NO | FC15: NO | FD15: NO | FE15: NO | FF15: N/A | FG15: NO | FH15: NO | FI15: NO | FJ15: NO | FK15: NO | FL15: N/A | FM15: NO | FN15: NO | FO15: NO | FP15: NO | FQ15: NO | FR15: N/A | FS15: NO | FT15: NO | FU15: NO | FV15: NO | FW15: NO | FX15: N/A | FY15: NO | FZ15: N/A | GA15: NO | GB15: NO | GC15: NO | GD15: NO | GE15: NO | GF15: NO | GG15: NO | GH15: N/A | GI15: NO | GJ15: N/A
A16: can_003 | B16: 2024 | C16: YES | D16: YES | E16: NO | F16: NO | G16: NO | H16: NO | I16: N/A | J16: YES | K16: YES | L16: YES | M16: YES | N16: YES | O16: YES | P16: NO | Q16: NO | R16: NO | S16: N/A | T16: NO | U16: N/A | V16: YES | W16: YES | X16: YES | Y16: YES | Z16: YES | AA16: NO | AB16: NO | AC16: NO | AD16: NO | AE16: NO | AF16: YES | AG16: N/A | AH16: YES | AI16: NO | AJ16: N/A | AK16: NO | AL16: N/A | AM16: NO | AN16: N/A | AO16: NO | AP16: NO | AQ16: NO | AR16: NO | AS16: NO | AT16: NO | AU16: NO | AV16: NO | AW16: N/A | AX16: NO | AY16: N/A | AZ16: NO | BA16: NO | BB16: NO | BC16: NO | BD16: N/A | BE16: NO | BF16: NO | BG16: N/A | BH16: NO | BI16: NO | BJ16: NO | BK16: NO | BL16: N/A | BM16: NO | BN16: N/A | BO16: NO | BP16: NO | BQ16: NO | BR16: NO | BS16: NO | BT16: NO | BU16: NO | BV16: N/A | BW16: YES | BX16: YES | BY16: YES | BZ16: NO | CA16: NO | CB16: NO | CC16: NO | CD16: NO | CE16: NO | CF16: NO | CG16: NO | CH16: YES | CI16: YES | CJ16: NO | CK16: NO | CL16: NO | CM16: YES | CN16: NO | CO16: NO | CP16: NO | CQ16: NO | CR16: NO | CS16: NO | CT16: NO | CU16: NO | CV16: NO | CW16: NO | CX16: NO | CY16: NO | CZ16: NO | DA16: NO | DB16: NO | DC16: NO | DD16: NO | DE16: NO | DF16: NO | DG16: NO | DH16: NO | DI16: NO | DJ16: NO | DK16: NO | DL16: N/A | DM16: NO | DN16: NO | DO16: NO | DP16: NO | DQ16: NO | DR16: NO | DS16: N/A | DT16: NO | DU16: NO | DV16: NO | DW16: NO | DX16: NO | DY16: N/A | DZ16: NO | EA16: NO | EB16: NO | EC16: NO | ED16: NO | EE16: N/A | EF16: NO | EG16: NO | EH16: NO | EI16: NO | EJ16: NO | EK16: N/A | EL16: NO | EM16: NO | EN16: NO | EO16: NO | EP16: NO | EQ16: N/A | ER16: NO | ES16: N/A | ET16: NO | EU16: NO | EV16: NO | EW16: NO | EX16: NO | EY16: NO | EZ16: N/A | FA16: NO | FB16: NO | FC16: NO | FD16: NO | FE16: NO | FF16: N/A | FG16: NO | FH16: NO | FI16: NO | FJ16: NO | FK16: NO | FL16: N/A | FM16: NO | FN16: NO | FO16: NO | FP16: NO | FQ16: NO | FR16: N/A | FS16: NO | FT16: NO | FU16: NO | FV16: NO | FW16: NO | FX16: N/A | FY16: NO | FZ16: N/A | GA16: NO | GB16: NO | GC16: NO | GD16: NO | GE16: NO | GF16: NO | GG16: NO | GH16: N/A | GI16: NO | GJ16: N/A
A17: can_004 | B17: 2025 | C17: YES | D17: YES | E17: NO | F17: NO | G17: YES | H17: NO | I17: N/A | J17: YES | K17: YES | L17: YES | M17: YES | N17: YES | O17: YES | P17: NO | Q17: NO | R17: NO | S17: N/A | T17: NO | U17: N/A | V17: YES | W17: YES | X17: YES | Y17: YES | Z17: YES | AA17: NO | AB17: NO | AC17: NO | AD17: NO | AE17: NO | AF17: YES | AG17: N/A | AH17: YES | AI17: NO | AJ17: N/A | AK17: NO | AL17: N/A | AM17: YES | AN17: keep medications at home, discuss with physician, carbon monoxide alarms | AO17: NO | AP17: NO | AQ17: NO | AR17: NO | AS17: NO | AT17: NO | AU17: NO | AV17: NO | AW17: N/A | AX17: NO | AY17: N/A | AZ17: NO | BA17: NO | BB17: NO | BC17: NO | BD17: N/A | BE17: NO | BF17: NO | BG17: N/A | BH17: NO | BI17: NO | BJ17: NO | BK17: NO | BL17: N/A | BM17: NO | BN17: N/A | BO17: NO | BP17: NO | BQ17: NO | BR17: NO | BS17: NO | BT17: NO | BU17: NO | BV17: N/A | BW17: YES | BX17: YES | BY17: YES | BZ17: NO | CA17: NO | CB17: NO | CC17: NO | CD17: NO | CE17: NO | CF17: NO | CG17: NO | CH17: NO | CI17: NO | CJ17: NO | CK17: NO | CL17: NO | CM17: NO | CN17: NO | CO17: NO | CP17: NO | CQ17: NO | CR17: NO | CS17: NO | CT17: NO | CU17: NO | CV17: NO | CW17: NO | CX17: NO | CY17: NO | CZ17: NO | DA17: NO | DB17: NO | DC17: NO | DD17: NO | DE17: NO | DF17: NO | DG17: NO | DH17: NO | DI17: NO | DJ17: NO | DK17: NO | DL17: N/A | DM17: NO | DN17: NO | DO17: NO | DP17: NO | DQ17: NO | DR17: NO | DS17: N/A | DT17: NO | DU17: NO | DV17: NO | DW17: NO | DX17: NO | DY17: N/A | DZ17: NO | EA17: NO | EB17: NO | EC17: NO | ED17: NO | EE17: N/A | EF17: NO | EG17: NO | EH17: NO | EI17: NO | EJ17: NO | EK17: N/A | EL17: NO | EM17: NO | EN17: NO | EO17: NO | EP17: NO | EQ17: N/A | ER17: NO | ES17: N/A | ET17: NO | EU17: NO | EV17: NO | EW17: NO | EX17: NO | EY17: NO | EZ17: N/A | FA17: NO | FB17: NO | FC17: NO | FD17: NO | FE17: NO | FF17: N/A | FG17: NO | FH17: NO | FI17: NO | FJ17: NO | FK17: NO | FL17: N/A | FM17: NO | FN17: NO | FO17: NO | FP17: NO | FQ17: NO | FR17: N/A | FS17: NO | FT17: NO | FU17: NO | FV17: NO | FW17: NO | FX17: N/A | FY17: NO | FZ17: N/A | GA17: NO | GB17: NO | GC17: NO | GD17: NO | GE17: NO | GF17: NO | GG17: NO | GH17: N/A | GI17: NO | GJ17: N/A
A18: bccdc_001 | B18: 2024 | C18: YES | D18: YES | E18: YES | F18: NO | G18: NO | H18: NO | I18: N/A | J18: YES | K18: YES | L18: NO | M18: NO | N18: NO | O18: NO | P18: NO | Q18: NO | R18: NO | S18: N/A | T18: NO | U18: N/A | V18: NO | W18: NO | X18: NO | Y18: NO | Z18: NO | AA18: NO | AB18: NO | AC18: NO | AD18: NO | AE18: NO | AF18: NO | AG18: N/A | AH18: NO | AI18: NO | AJ18: N/A | AK18: NO | AL18: N/A | AM18: NO | AN18: N/A | AO18: NO | AP18: NO | AQ18: NO | AR18: NO | AS18: NO | AT18: NO | AU18: NO | AV18: NO | AW18: N/A | AX18: NO | AY18: N/A | AZ18: NO | BA18: NO | BB18: NO | BC18: NO | BD18: N/A | BE18: NO | BF18: NO | BG18: N/A | BH18: NO | BI18: NO | BJ18: NO | BK18: NO | BL18: N/A | BM18: NO | BN18: N/A | BO18: NO | BP18: NO | BQ18: NO | BR18: NO | BS18: NO | BT18: NO | BU18: NO | BV18: N/A | BW18: YES | BX18: YES | BY18: YES | BZ18: NO | CA18: NO | CB18: NO | CC18: YES | CD18: YES | CE18: NO | CF18: NO | CG18: NO | CH18: YES | CI18: YES | CJ18: NO | CK18: NO | CL18: NO | CM18: NO | CN18: NO | CO18: NO | CP18: NO | CQ18: NO | CR18: NO | CS18: NO | CT18: NO | CU18: NO | CV18: NO | CW18: NO | CX18: NO | CY18: NO | CZ18: NO | DA18: NO | DB18: NO | DC18: NO | DD18: NO | DE18: NO | DF18: NO | DG18: NO | DH18: NO | DI18: NO | DJ18: NO | DK18: NO | DL18: N/A | DM18: NO | DN18: NO | DO18: NO | DP18: NO | DQ18: NO | DR18: NO | DS18: N/A | DT18: NO | DU18: NO | DV18: NO | DW18: NO | DX18: NO | DY18: N/A | DZ18: NO | EA18: NO | EB18: NO | EC18: NO | ED18: NO | EE18: N/A | EF18: NO | EG18: NO | EH18: NO | EI18: NO | EJ18: NO | EK18: N/A | EL18: NO | EM18: NO | EN18: NO | EO18: NO | EP18: NO | EQ18: N/A | ER18: NO | ES18: N/A | ET18: NO | EU18: NO | EV18: NO | EW18: NO | EX18: NO | EY18: NO | EZ18: N/A | FA18: NO | FB18: NO | FC18: NO | FD18: NO | FE18: NO | FF18: N/A | FG18: NO | FH18: NO | FI18: NO | FJ18: NO | FK18: NO | FL18: N/A | FM18: NO | FN18: NO | FO18: NO | FP18: NO | FQ18: NO | FR18: N/A | FS18: NO | FT18: NO | FU18: NO | FV18: NO | FW18: NO | FX18: N/A | FY18: NO | FZ18: N/A | GA18: NO | GB18: NO | GC18: NO | GD18: NO | GE18: NO | GF18: NO | GG18: NO | GH18: N/A | GI18: NO | GJ18: N/A
